Workbook

Sheet Scores
B2: Naam cursist | C2: Huda
D3: Luisteren | E3: Schrijven | F3: Lezen | G3: Grammatica | H3: Spreken
B4: Deel | C4: Thema | D4: Score (%) | E4: Score (%) | F4: Score (%) | G4: Score (%) | H4: Score (%) | I4: Extra
B5: A1 | C5: A1-1 | D5: 75 | E5: 86 | F5: 40 | G5: 33 | H5: 60 | I5: 0
C6: A1-2 | D6: 60 | E6: 50 | F6: 100 | G6: 62 | H6: 45 | I6: =I5+5 -> 5
C7: A1-3 | I7: =I6+5 -> 10
C8: A1-4 | I8: =I7+5 -> 15
C9: A1-5 | I9: =I8+5 -> 20
C10: A1-6 | I10: =I9+5 -> 25
C11: A1-7 | I11: =I10+5 -> 30
C12: A1-8 | I12: =I11+5 -> 35
B13: A2 | C13: A2-1 | I13: =I12+5 -> 40
C14: A2-2 | I14: =I13+5 -> 45
C15: A2-3 | I15: =I14+5 -> 50
C16: A2-4 | I16: =I15+5 -> 55
C17: A2-5 | I17: =I16+5 -> 60
C18: A2-6 | I18: =I17+5 -> 65
C19: A2-7 | I19: =I18+5 -> 70
C20: A2-8 | I20: =I19+5 -> 75

Sheet Overzicht
C2: Scores van cursist: | D2: =Scores!C2 -> Huda
C5: Luisteren
A6: Deel | B6: Thema | C6: Score (%)
A7: A1 | B7: A1-1 | C7: =Scores!D5 -> 75
B8: A1-2 | C8: =Scores!D6 -> 60
B9: A1-3 | C9: =Scores!D7 -> 0
B10: A1-4 | C10: =Scores!D8 -> 0
B11: A1-5 | C11: =Scores!D9 -> 0
B12: A1-6 | C12: =Scores!D10 -> 0
B13: A1-7 | C13: =Scores!D11 -> 0
B14: A1-8 | C14: =Scores!D12 -> 0
A15: A2 | B15: A2-1 | C15: =Scores!D13 -> 0
B16: A2-2 | C16: =Scores!D14 -> 0
B17: A2-3 | C17: =Scores!D15 -> 0
B18: A2-4 | C18: =Scores!D16 -> 0
B19: A2-5 | C19: =Scores!D17 -> 0
B20: A2-6 | C20: =Scores!D18 -> 0
B21: A2-7 | C21: =Scores!D19 -> 0
B22: A2-8 | C22: =Scores!D20 -> 0
C31: Schrijven
A32: Deel | B32: Thema | C32: Score (%)
A33: A1 | B33: A1-1 | C33: =Scores!E5 -> 86
B34: A1-2 | C34: =Scores!E6 -> 50
B35: A1-3 | C35: =Scores!E7 -> 0
B36: A1-4 | C36: =Scores!E8 -> 0
B37: A1-5 | C37: =Scores!E9 -> 0
B38: A1-6 | C38: =Scores!E10 -> 0
B39: A1-7 | C39: =Scores!E11 -> 0
B40: A1-8 | C40: =Scores!E12 -> 0
A41: A2 | B41: A2-1 | C41: =Scores!E13 -> 0
B42: A2-2 | C42: =Scores!E14 -> 0
B43: A2-3 | C43: =Scores!E15 -> 0
B44: A2-4 | C44: =Scores!E16 -> 0
B45: A2-5 | C45: =Scores!E17 -> 0
B46: A2-6 | C46: =Scores!E18 -> 0
B47: A2-7 | C47: =Scores!E19 -> 0
B48: A2-8 | C48: =Scores!E20 -> 0
C57: Lezen
A58: Deel | B58: Thema | C58: Score (%)
A59: A1 | B59: A1-1 | C59: =Scores!F5 -> 40
...

Sheet Luisteren
B2: Onderdeel | C2: Luisteren
B4: Deel | C4: Thema | D4: Score (percentage) | E4: Resultaten | F4: Streeflijn (67%)
B5: A1 | C5: =Scores!C5 -> A1-1 | D5: =Scores!D5 -> 75 | E5: =IF(D5>0,D5+Scores!I5,NA()) -> 75 | F5: =67+Scores!I5 -> 67
C6: =Scores!C6 -> A1-2 | D6: =Scores!D6 -> 60 | E6: =IF(D6>0,D6+Scores!I6,NA()) -> 65 | F6: =$F$5+Scores!I6 -> 72
C7: =Scores!C7 -> A1-3 | D7: =Scores!D7 -> 0 | E7: =IF(D7>0,D7+Scores!I7,NA()) -> #N/A | F7: =$F$5+Scores!I7 -> 77
C8: =Scores!C8 -> A1-4 | D8: =Scores!D8 -> 0 | E8: =IF(D8>0,D8+Scores!I8,NA()) -> #N/A | F8: =$F$5+Scores!I8 -> 82
C9: =Scores!C9 -> A1-5 | D9: =Scores!D9 -> 0 | E9: =IF(D9>0,D9+Scores!I9,NA()) -> #N/A | F9: =$F$5+Scores!I9 -> 87
C10: =Scores!C10 -> A1-6 | D10: =Scores!D10 -> 0 | E10: =IF(D10>0,D10+Scores!I10,NA()) -> #N/A | F10: =$F$5+Scores!I10 -> 92
C11: =Scores!C11 -> A1-7 | D11: =Scores!D11 -> 0 | E11: =IF(D11>0,D11+Scores!I11,NA()) -> #N/A | F11: =$F$5+Scores!I11 -> 97
C12: =Scores!C12 -> A1-8 | D12: =Scores!D12 -> 0 | E12: =IF(D12>0,D12+Scores!I12,NA()) -> #N/A | F12: =$F$5+Scores!I12 -> 102
B13: A2 | C13: =Scores!C13 -> A2-1 | D13: =Scores!D13 -> 0 | E13: =IF(D13>0,D13+Scores!I13,NA()) -> #N/A | F13: =$F$5+Scores!I13 -> 107
C14: =Scores!C14 -> A2-2 | D14: =Scores!D14 -> 0 | E14: =IF(D14>0,D14+Scores!I14,NA()) -> #N/A | F14: =$F$5+Scores!I14 -> 112
C15: =Scores!C15 -> A2-3 | D15: =Scores!D15 -> 0 | E15: =IF(D15>0,D15+Scores!I15,NA()) -> #N/A | F15: =$F$5+Scores!I15 -> 117
C16: =Scores!C16 -> A2-4 | D16: =Scores!D16 -> 0 | E16: =IF(D16>0,D16+Scores!I16,NA()) -> #N/A | F16: =$F$5+Scores!I16 -> 122
C17: =Scores!C17 -> A2-5 | D17: =Scores!D17 -> 0 | E17: =IF(D17>0,D17+Scores!I17,NA()) -> #N/A | F17: =$F$5+Scores!I17 -> 127
C18: =Scores!C18 -> A2-6 | D18: =Scores!D18 -> 0 | E18: =IF(D18>0,D18+Scores!I18,NA()) -> #N/A | F18: =$F$5+Scores!I18 -> 132
C19: =Scores!C19 -> A2-7 | D19: =Scores!D19 -> 0 | E19: =IF(D19>0,D19+Scores!I19,NA()) -> #N/A | F19: =$F$5+Scores!I19 -> 137
C20: =Scores!C20 -> A2-8 | D20: =Scores!D20 -> 0 | E20: =IF(D20>0,D20+Scores!I20,NA()) -> #N/A | F20: =$F$5+Scores!I20 -> 142

Sheet Schrijven
B2: Onderdeel | C2: Schrijven
B4: Deel | C4: Thema | D4: Score (percentage) | E4: Resultaten | F4: Streeflijn (67%)
B5: A1 | C5: =Scores!C5 -> A1-1 | D5: =Scores!E5 -> 86 | E5: =IF(D5>0,D5+Scores!I5,NA()) -> 86 | F5: =67+Scores!I5 -> 67
C6: =Scores!C6 -> A1-2 | D6: =Scores!E6 -> 50 | E6: =IF(D6>0,D6+Scores!I6,NA()) -> 55 | F6: =$F$5+Scores!I6 -> 72
C7: =Scores!C7 -> A1-3 | D7: =Scores!E7 -> 0 | E7: =IF(D7>0,D7+Scores!I7,NA()) -> #N/A | F7: =$F$5+Scores!I7 -> 77
C8: =Scores!C8 -> A1-4 | D8: =Scores!E8 -> 0 | E8: =IF(D8>0,D8+Scores!I8,NA()) -> #N/A | F8: =$F$5+Scores!I8 -> 82
C9: =Scores!C9 -> A1-5 | D9: =Scores!E9 -> 0 | E9: =IF(D9>0,D9+Scores!I9,NA()) -> #N/A | F9: =$F$5+Scores!I9 -> 87
C10: =Scores!C10 -> A1-6 | D10: =Scores!E10 -> 0 | E10: =IF(D10>0,D10+Scores!I10,NA()) -> #N/A | F10: =$F$5+Scores!I10 -> 92
C11: =Scores!C11 -> A1-7 | D11: =Scores!E11 -> 0 | E11: =IF(D11>0,D11+Scores!I11,NA()) -> #N/A | F11: =$F$5+Scores!I11 -> 97
C12: =Scores!C12 -> A1-8 | D12: =Scores!E12 -> 0 | E12: =IF(D12>0,D12+Scores!I12,NA()) -> #N/A | F12: =$F$5+Scores!I12 -> 102
B13: A2 | C13: =Scores!C13 -> A2-1 | D13: =Scores!E13 -> 0 | E13: =IF(D13>0,D13+Scores!I13,NA()) -> #N/A | F13: =$F$5+Scores!I13 -> 107
C14: =Scores!C14 -> A2-2 | D14: =Scores!E14 -> 0 | E14: =IF(D14>0,D14+Scores!I14,NA()) -> #N/A | F14: =$F$5+Scores!I14 -> 112
C15: =Scores!C15 -> A2-3 | D15: =Scores!E15 -> 0 | E15: =IF(D15>0,D15+Scores!I15,NA()) -> #N/A | F15: =$F$5+Scores!I15 -> 117
C16: =Scores!C16 -> A2-4 | D16: =Scores!E16 -> 0 | E16: =IF(D16>0,D16+Scores!I16,NA()) -> #N/A | F16: =$F$5+Scores!I16 -> 122
C17: =Scores!C17 -> A2-5 | D17: =Scores!E17 -> 0 | E17: =IF(D17>0,D17+Scores!I17,NA()) -> #N/A | F17: =$F$5+Scores!I17 -> 127
C18: =Scores!C18 -> A2-6 | D18: =Scores!E18 -> 0 | E18: =IF(D18>0,D18+Scores!I18,NA()) -> #N/A | F18: =$F$5+Scores!I18 -> 132
C19: =Scores!C19 -> A2-7 | D19: =Scores!E19 -> 0 | E19: =IF(D19>0,D19+Scores!I19,NA()) -> #N/A | F19: =$F$5+Scores!I19 -> 137
C20: =Scores!C20 -> A2-8 | D20: =Scores!E20 -> 0 | E20: =IF(D20>0,D20+Scores!I20,NA()) -> #N/A | F20: =$F$5+Scores!I20 -> 142

Sheet Lezen
B2: Onderdeel | C2: Lezen
B4: Deel | C4: Thema | D4: Score (percentage) | E4: Resultaten | F4: Streeflijn (67%)
B5: A1 | C5: =Scores!C5 -> A1-1 | D5: =Scores!F5 -> 40 | E5: =IF(D5>0,D5+Scores!I5,NA()) -> 40 | F5: =67+Scores!I5 -> 67
C6: =Scores!C6 -> A1-2 | D6: =Scores!F6 -> 100 | E6: =IF(D6>0,D6+Scores!I6,NA()) -> 105 | F6: =$F$5+Scores!I6 -> 72
C7: =Scores!C7 -> A1-3 | D7: =Scores!F7 -> 0 | E7: =IF(D7>0,D7+Scores!I7,NA()) -> #N/A | F7: =$F$5+Scores!I7 -> 77
C8: =Scores!C8 -> A1-4 | D8: =Scores!F8 -> 0 | E8: =IF(D8>0,D8+Scores!I8,NA()) -> #N/A | F8: =$F$5+Scores!I8 -> 82
C9: =Scores!C9 -> A1-5 | D9: =Scores!F9 -> 0 | E9: =IF(D9>0,D9+Scores!I9,NA()) -> #N/A | F9: =$F$5+Scores!I9 -> 87
C10: =Scores!C10 -> A1-6 | D10: =Scores!F10 -> 0 | E10: =IF(D10>0,D10+Scores!I10,NA()) -> #N/A | F10: =$F$5+Scores!I10 -> 92
C11: =Scores!C11 -> A1-7 | D11: =Scores!F11 -> 0 | E11: =IF(D11>0,D11+Scores!I11,NA()) -> #N/A | F11: =$F$5+Scores!I11 -> 97
C12: =Scores!C12 -> A1-8 | D12: =Scores!F12 -> 0 | E12: =IF(D12>0,D12+Scores!I12,NA()) -> #N/A | F12: =$F$5+Scores!I12 -> 102
B13: A2 | C13: =Scores!C13 -> A2-1 | D13: =Scores!F13 -> 0 | E13: =IF(D13>0,D13+Scores!I13,NA()) -> #N/A | F13: =$F$5+Scores!I13 -> 107
C14: =Scores!C14 -> A2-2 | D14: =Scores!F14 -> 0 | E14: =IF(D14>0,D14+Scores!I14,NA()) -> #N/A | F14: =$F$5+Scores!I14 -> 112
C15: =Scores!C15 -> A2-3 | D15: =Scores!F15 -> 0 | E15: =IF(D15>0,D15+Scores!I15,NA()) -> #N/A | F15: =$F$5+Scores!I15 -> 117
C16: =Scores!C16 -> A2-4 | D16: =Scores!F16 -> 0 | E16: =IF(D16>0,D16+Scores!I16,NA()) -> #N/A | F16: =$F$5+Scores!I16 -> 122
C17: =Scores!C17 -> A2-5 | D17: =Scores!F17 -> 0 | E17: =IF(D17>0,D17+Scores!I17,NA()) -> #N/A | F17: =$F$5+Scores!I17 -> 127
C18: =Scores!C18 -> A2-6 | D18: =Scores!F18 -> 0 | E18: =IF(D18>0,D18+Scores!I18,NA()) -> #N/A | F18: =$F$5+Scores!I18 -> 132
C19: =Scores!C19 -> A2-7 | D19: =Scores!F19 -> 0 | E19: =IF(D19>0,D19+Scores!I19,NA()) -> #N/A | F19: =$F$5+Scores!I19 -> 137
C20: =Scores!C20 -> A2-8 | D20: =Scores!F20 -> 0 | E20: =IF(D20>0,D20+Scores!I20,NA()) -> #N/A | F20: =$F$5+Scores!I20 -> 142

Sheet Grammatica
B2: Onderdeel | C2: Grammatica
B4: Deel | C4: Thema | D4: Score (percentage) | E4: Resultaten | F4: Streeflijn (67%)
B5: A1 | C5: =Scores!C5 -> A1-1 | D5: =Scores!G5 -> 33 | E5: =IF(D5>0,D5+Scores!I5,NA()) -> 33 | F5: =67+Scores!I5 -> 67
C6: =Scores!C6 -> A1-2 | D6: =Scores!G6 -> 62 | E6: =IF(D6>0,D6+Scores!I6,NA()) -> 67 | F6: =$F$5+Scores!I6 -> 72
C7: =Scores!C7 -> A1-3 | D7: =Scores!G7 -> 0 | E7: =IF(D7>0,D7+Scores!I7,NA()) -> #N/A | F7: =$F$5+Scores!I7 -> 77
C8: =Scores!C8 -> A1-4 | D8: =Scores!G8 -> 0 | E8: =IF(D8>0,D8+Scores!I8,NA()) -> #N/A | F8: =$F$5+Scores!I8 -> 82
C9: =Scores!C9 -> A1-5 | D9: =Scores!G9 -> 0 | E9: =IF(D9>0,D9+Scores!I9,NA()) -> #N/A | F9: =$F$5+Scores!I9 -> 87
C10: =Scores!C10 -> A1-6 | D10: =Scores!G10 -> 0 | E10: =IF(D10>0,D10+Scores!I10,NA()) -> #N/A | F10: =$F$5+Scores!I10 -> 92
C11: =Scores!C11 -> A1-7 | D11: =Scores!G11 -> 0 | E11: =IF(D11>0,D11+Scores!I11,NA()) -> #N/A | F11: =$F$5+Scores!I11 -> 97
C12: =Scores!C12 -> A1-8 | D12: =Scores!G12 -> 0 | E12: =IF(D12>0,D12+Scores!I12,NA()) -> #N/A | F12: =$F$5+Scores!I12 -> 102
B13: A2 | C13: =Scores!C13 -> A2-1 | D13: =Scores!G13 -> 0 | E13: =IF(D13>0,D13+Scores!I13,NA()) -> #N/A | F13: =$F$5+Scores!I13 -> 107
C14: =Scores!C14 -> A2-2 | D14: =Scores!G14 -> 0 | E14: =IF(D14>0,D14+Scores!I14,NA()) -> #N/A | F14: =$F$5+Scores!I14 -> 112
C15: =Scores!C15 -> A2-3 | D15: =Scores!G15 -> 0 | E15: =IF(D15>0,D15+Scores!I15,NA()) -> #N/A | F15: =$F$5+Scores!I15 -> 117
C16: =Scores!C16 -> A2-4 | D16: =Scores!G16 -> 0 | E16: =IF(D16>0,D16+Scores!I16,NA()) -> #N/A | F16: =$F$5+Scores!I16 -> 122
C17: =Scores!C17 -> A2-5 | D17: =Scores!G17 -> 0 | E17: =IF(D17>0,D17+Scores!I17,NA()) -> #N/A | F17: =$F$5+Scores!I17 -> 127
C18: =Scores!C18 -> A2-6 | D18: =Scores!G18 -> 0 | E18: =IF(D18>0,D18+Scores!I18,NA()) -> #N/A | F18: =$F$5+Scores!I18 -> 132
C19: =Scores!C19 -> A2-7 | D19: =Scores!G19 -> 0 | E19: =IF(D19>0,D19+Scores!I19,NA()) -> #N/A | F19: =$F$5+Scores!I19 -> 137
C20: =Scores!C20 -> A2-8 | D20: =Scores!G20 -> 0 | E20: =IF(D20>0,D20+Scores!I20,NA()) -> #N/A | F20: =$F$5+Scores!I20 -> 142

Sheet Spreken
B2: Onderdeel | C2: Spreken
B4: Deel | C4: Thema | D4: Score (percentage) | E4: Resultaten | F4: Streeflijn (67%)
B5: A1 | C5: =Scores!C5 -> A1-1 | D5: =Scores!H5 -> 60 | E5: =IF(D5>0,D5+Scores!I5,NA()) -> 60 | F5: =67+Scores!I5 -> 67
C6: =Scores!C6 -> A1-2 | D6: =Scores!H6 -> 45 | E6: =IF(D6>0,D6+Scores!I6,NA()) -> 50 | F6: =$F$5+Scores!I6 -> 72
C7: =Scores!C7 -> A1-3 | D7: =Scores!H7 -> 0 | E7: =IF(D7>0,D7+Scores!I7,NA()) -> #N/A | F7: =$F$5+Scores!I7 -> 77
C8: =Scores!C8 -> A1-4 | D8: =Scores!H8 -> 0 | E8: =IF(D8>0,D8+Scores!I8,NA()) -> #N/A | F8: =$F$5+Scores!I8 -> 82
C9: =Scores!C9 -> A1-5 | D9: =Scores!H9 -> 0 | E9: =IF(D9>0,D9+Scores!I9,NA()) -> #N/A | F9: =$F$5+Scores!I9 -> 87
C10: =Scores!C10 -> A1-6 | D10: =Scores!H10 -> 0 | E10: =IF(D10>0,D10+Scores!I10,NA()) -> #N/A | F10: =$F$5+Scores!I10 -> 92
C11: =Scores!C11 -> A1-7 | D11: =Scores!H11 -> 0 | E11: =IF(D11>0,D11+Scores!I11,NA()) -> #N/A | F11: =$F$5+Scores!I11 -> 97
C12: =Scores!C12 -> A1-8 | D12: =Scores!H12 -> 0 | E12: =IF(D12>0,D12+Scores!I12,NA()) -> #N/A | F12: =$F$5+Scores!I12 -> 102
B13: A2 | C13: =Scores!C13 -> A2-1 | D13: =Scores!H13 -> 0 | E13: =IF(D13>0,D13+Scores!I13,NA()) -> #N/A | F13: =$F$5+Scores!I13 -> 107
C14: =Scores!C14 -> A2-2 | D14: =Scores!H14 -> 0 | E14: =IF(D14>0,D14+Scores!I14,NA()) -> #N/A | F14: =$F$5+Scores!I14 -> 112
C15: =Scores!C15 -> A2-3 | D15: =Scores!H15 -> 0 | E15: =IF(D15>0,D15+Scores!I15,NA()) -> #N/A | F15: =$F$5+Scores!I15 -> 117
C16: =Scores!C16 -> A2-4 | D16: =Scores!H16 -> 0 | E16: =IF(D16>0,D16+Scores!I16,NA()) -> #N/A | F16: =$F$5+Scores!I16 -> 122
C17: =Scores!C17 -> A2-5 | D17: =Scores!H17 -> 0 | E17: =IF(D17>0,D17+Scores!I17,NA()) -> #N/A | F17: =$F$5+Scores!I17 -> 127
C18: =Scores!C18 -> A2-6 | D18: =Scores!H18 -> 0 | E18: =IF(D18>0,D18+Scores!I18,NA()) -> #N/A | F18: =$F$5+Scores!I18 -> 132
C19: =Scores!C19 -> A2-7 | D19: =Scores!H19 -> 0 | E19: =IF(D19>0,D19+Scores!I19,NA()) -> #N/A | F19: =$F$5+Scores!I19 -> 137
C20: =Scores!C20 -> A2-8 | D20: =Scores!H20 -> 0 | E20: =IF(D20>0,D20+Scores!I20,NA()) -> #N/A | F20: =$F$5+Scores!I20 -> 142
